Workbook
Name Slicer_Channel: #N/A
Name Slicer_Country: #N/A
Name Slicer_Months__OrderDate: #N/A
Name Slicer_ProductCategory: #N/A
Name Slicer_Region: #N/A
Name Slicer_Salesperson: #N/A

Sheet Data
A1: OrderID | B1: OrderDate | C1: RequiredDate | D1: Region | E1: Country | F1: City | G1: CustomerSegment | H1: Channel | I1: Salesperson | J1: ProductCategory | K1: SKU | L1: UnitCost | M1: UnitPrice | N1: DiscountPct | O1: Quantity
A2: ORD-2024-275203 | B2: 45362 | C2: 45388 | D2: Africa | E2: Kenya | F2: Kisumu | G2: Corporate | H2: Retail | I2: C. Otieno | J2: Components | K2: CMP-8270 | L2: 279.24 | M2: 608.9 | N2: 0.112 | O2: 9
A3: ORD-2024-358795 | B3: 45588 | C3: 45587 | D3: Africa | E3: Nigeria | F3: Port Harcourt | G3: Education | H3: Online | I3: J. Njeri | J3: Printers | K3: PRN-9322 | L3: 1084.39 | M3: 759.33 | N3: 0.237 | O3: 31
A4: ORD-2023-373538 | B4: 44985 | C4: 45010 | D4: Africa | E4: Kenya | F4: Nairobi | G4: Corporate | H4: Retail | I4: I. Johnson | J4: Networking | K4: NET-9666 | L4: 1460.76 | M4: -30.66 | N4: 0.131 | O4: 12
A5: ORD-2025-168148 | B5: 45745 | C5: 45749 | D5: Africa | E5: Nigeria | F5: Lagos | G5: Non-Profit | H5: Marketplace | I5: G. Dubois | J5: Phones | K5: PHN-4556 | L5: 259.93 | M5: 255.94 | N5: 0.072 | O5: 22
A6: ORD-2023-824839 | B6: 45266 | C6: 45291 | D6: Asia | E6: Japan | F6: Osaka | G6: Consumer | H6: Retail | I6: L. Okafor | J6: Printers | K6: PRN-8041 | L6: 663.03 | M6: 813.51 | N6: 0.102 | O6: 15
A7: ORD-2023-723587 | B7: 44928 | C7: 44931 | D7: Americas | E7: Canada | F7: Toronto | G7: Corporate | H7: Distributor | I7: B. Chen | J7: Laptops | K7: LAP-8555 | L7: 315.87 | M7: 591.68 | N7: 0 | O7: 7
A8: ORD-2024-336584 | B8: 45653 | C8: 45671 | D8: Asia | E8: India | F8: Bengaluru | G8: Small Business | H8: Marketplace | I8: E. Garcia | J8: Monitors | K8: MON-8629 | L8: 586.07 | M8: 845.97 | N8: 0.147 | O8: 4
A9: ORD-2023-112666 | B9: 44941 | C9: 44939 | D9: Africa | E9: Nigeria | F9: Abuja | G9: Education | H9: Online | I9: O. Wang | J9: Printers | K9: PRN-6276 | L9: 28.38 | M9: 47.22 | N9: 0.194 | O9: 18
A10: ORD-2024-589570 | B10: 45416 | C10: 45441 | D10: Africa | E10: Nigeria | F10: Abuja | G10: Non-Profit | H10: Marketplace | I10: O. Wang | J10: Monitors | K10: MON-6892 | L10: 1295.34 | M10: 2530.81 | N10: 0.031 | O10: 6
A11: ORD-2025-997421 | B11: 45798 | C11: 45817 | D11: Americas | E11: Brazil | F11: São Paulo | G11: Non-Profit | H11: Online | I11: A. Patel | J11: Components | K11: CMP-3731 | L11: 1331.38 | M11: 2309.56 | N11: 0.149 | O11: 31
A12: ORD-2024-210687 | B12: 45319 | C12: 45331 | D12: Europe | E12: Germany | F12: Berlin | G12: Corporate | H12: Online | I12: G. Dubois | J12: Accessories | K12: ACC-7938 | L12: 644.17 | M12: 700.12 | N12: 0.006 | O12: 23
A13: ORD-2025-515515 | B13: 45660 | C13: 45680 | D13: Asia | E13: Japan | F13: Osaka | G13: Corporate | H13: Distributor | I13: F. Müller | J13: Phones | K13: PHN-7019 | L13: 908.6 | M13: 691.37 | N13: 0.25 | O13: 20
... A34: ORD-2025-474710 | B34: 45862 | C34: 45875 | D34: Africa | E34: South Africa | F34: Johannesburg | G34: Education | H34: Marketplace | I34: D. Smith | J34: Networking | K34: NET-7966 | L34: 1463.9 | M34: 2633.02 | N34: 0.084 | O34: 4
A35: ORD-2024-629525 | B35: 45400 | C35: 45420 | D35: Europe | E35: United Kingdom | F35: London | G35: Non-Profit | I35: D. Smith | J35: Laptops | K35: LAP-9932 | L35: 645.33 | M35: 1321.85 | N35: 0 | O35: 10
A36: ORD-2024-167215 | B36: 45527 | C36: 45525 | D36: Africa | E36: South Africa | F36: Johannesburg | G36: Education | H36: Retail | I36: E. Garcia | J36: Components | K36: CMP-1559 | L36: 1432.52 | M36: 3036.87 | N36: 0 | O36: 9
A37: ORD-2023-864121 | B37: 45012 | C37: 45038 | D37: Asia | E37: India | F37: Delhi | G37: Non-Profit | H37: Marketplace | I37: J. Njeri | J37: Printers | K37: PRN-4506 | L37: 178.53 | M37: 199.37 | N37: 0.101 | O37: 37
A38: ORD-2024-692673 | B38: 45358 | C38: 45376 | D38: Europe | E38: Germany | F38: Munich | G38: Corporate | H38: Online | I38: B. Chen | J38: Components | K38: CMP-7617 | L38: 712.84 | M38: 927.51 | N38: 0.243 | O38: 27
A39: ORD-2025-718992 | B39: 45832 | C39: 45848 | D39: Asia | E39: China | F39: Shanghai | G39: Enterprise | H39: Direct | I39: N. Brown | J39: Components | K39: CMP-8390 | L39: 757.19 | M39: 1735.41 | N39: 0.136 | O39: 8
A40: ORD-2024-599522 | B40: 45401 | C40: 45418 | D40: Africa | E40: Nigeria | F40: Port Harcourt | G40: Non-Profit | H40: Online | I40: A. Patel | J40: Printers | K40: PRN-7303 | L40: 865.33 | M40: 1395.64 | N40: 0.175 | O40: 13
A41: ORD-2023-651638 | B41: 45094 | C41: 45101 | D41: Americas | E41: USA | F41: San Francisco | G41: Corporate | H41: Retail | I41: I. Johnson | J41: Printers | K41: PRN-6536 | L41: 313.99 | M41: 454.42 | N41: 0.129 | O41: 9
A42: ORD-2024-635626 | B42: 45531 | C42: 45554 | D42: Europe | E42: Germany | F42: Berlin | G42: Small Business | H42: Direct | I42: D. Smith | J42: Monitors | K42: MON-9967 | L42: 1024.01 | M42: 1580.97 | N42: 0.037 | O42: 27
A43: ORD-2024-296582 | B43: 45302 | C43: 45324 | D43: Africa | E43: South Africa | F43: Durban | G43: Consumer | H43: Online | I43: K. Singh | J43: Networking | K43: NET-1412 | L43: 1206.2 | M43: 1759.79 | N43: 0 | O43: 6
A44: ORD-2024-998320 | B44: 45590 | C44: 45610 | D44: Africa | E44: Kenya | F44: Mombasa | G44: Corporate | H44: Direct | I44: H. Kim | J44: Printers | K44: PRN-3143 | L44: 1396.48 | M44: 3204.5 | N44: 0.318 | O44: 14
A45: ORD-2025-820255 | B45: 45806 | C45: 45828 | D45: Europe | E45: Germany | F45: Berlin | G45: Corporate | H45: Direct | I45: A. Patel | J45: Printers | K45: PRN-9787 | L45: 483.47 | M45: 1135.43 | N45: 0.146 | O45: 11
A46: ORD-2024-389336 | B46: 45432 | C46: 45445 | D46: Americas | E46: Canada | F46: Vancouver | G46: Enterprise | H46: Marketplace | I46: K. Singh | J46: Components | K46: CMP-5946 | L46: 675.43 | M46: 996.36 | N46: 0.182 | O46: 22
A47: ORD-2023-308124 | B47: 45035 | C47: 45046 | D47: Asia | E47: India | F47: Delhi | G47: Small Business | H47: Retail | I47: A. Patel | J47: Networking | K47: NET-2062 | L47: 826.55 | M47: 1397.05 | N47: 0.169 | O47: 28
... A77: ORD-2023-722117 | B77: 45187 | C77: 45207 | D77: Asia | E77: India | F77: Delhi | G77: Small Business | H77: Direct | I77: B. Chen | J77: Components | K77: CMP-1009 | L77: 825.64 | M77: 1108.43 | N77: 0.114 | O77: 7
A78: ORD-2024-446699 | B78: 45532 | C78: 45560 | D78: Americas | E78: Brazil | F78: Rio de Janeiro | G78: Non-Profit | H78: Online | J78: Accessories | K78: ACC-4490 | L78: 1394.65 | M78: 3144.1 | N78: 0.134 | O78: 13
A79: ORD-2024-451005 | B79: 45473 | C79: 45471 | D79: Americas | E79: Brazil | F79: Rio de Janeiro | G79: Small Business | H79: Direct | I79: L. Okafor | J79: Accessories | K79: ACC-9162 | L79: 1112.98 | M79: 2095.73 | N79: 0.072 | O79: 17
A80: ORD-2023-290279 | B80: 45091 | C80: 45093 | D80: Europe | E80: United Kingdom | F80: Manchester | G80: Non-Profit | H80: Direct | I80: K. Singh | J80: Components | K80: CMP-5820 | L80: 357.36 | M80: 703.62 | N80: 0.257 | O80: 20
A81: ORD-2024-192263 | B81: 45617 | C81: 45647 | D81: Europe | E81: France | F81: Marseille | G81: Small Business | H81: Direct | I81: I. Johnson | J81: Monitors | K81: MON-7943 | L81: 1122.68 | M81: 1997.19 | N81: 0.186 | O81: 3
A82: ORD-2023-159379 | B82: 44965 | C82: 44968 | D82: Africa | E82: South Africa | F82: Cape Town | G82: Corporate | H82: Direct | I82: M. Rossi | J82: Networking | K82: NET-5018 | L82: 1410.05 | M82: 2763.95 | N82: 0.161 | O82: 26
A83: ORD-2023-343322 | B83: 45157 | C83: 45181 | D83: Americas | E83: Canada | F83: Vancouver | G83: Enterprise | H83: Retail | I83: I. Johnson | J83: Printers | K83: PRN-9669 | L83: 1183.95 | M83: 1503.53 | N83: 0.241 | O83: 16
A84: ORD-2025-114382 | B84: 45791 | C84: 45801 | D84: Europe | E84: France | F84: Paris | G84: Small Business | H84: Marketplace | I84: K. Singh | J84: Components | K84: CMP-2865 | L84: 170.39 | M84: 388.04 | N84: 0.084 | O84: 15
A85: ORD-2025-488349 | B85: 45770 | C85: 45769 | D85: Americas | E85: USA | F85: San Francisco | G85: Non-Profit | H85: Distributor | I85: D. Smith | J85: Monitors | K85: MON-3371 | L85: 23.24 | M85: 44.57 | N85: 0.215 | O85: 15
A86: ORD-2025-330203 | B86: 45741 | C86: 45764 | D86: Europe | E86: United Kingdom | F86: London | G86: Consumer | H86: Retail | I86: H. Kim | J86: Networking | K86: NET-7166 | L86: 1421.19 | M86: 1808.26 | N86: 0.104 | O86: 13
A87: ORD-2023-841426 | B87: 45282 | C87: 45283 | D87: Africa | E87: South Africa | F87: Cape Town | G87: Non-Profit | H87: Marketplace | I87: D. Smith | J87: Components | K87: CMP-4531 | L87: 1186.18 | M87: 1285.09 | N87: 0.07 | O87: 11
A88: ORD-2024-594592 | B88: 45388 | C88: 45407 | D88: Asia | E88: China | F88: Shanghai | G88: Corporate | H88: Retail | I88: K. Singh | J88: Components | K88: CMP-8196 | L88: 1366.48 | M88: 1678.14 | N88: 0.154 | O88: 10
A89: ORD-2025-863978 | B89: 45876 | C89: 45888 | D89: Africa | E89: Kenya | F89: Nakuru | G89: Corporate | I89: M. Rossi | J89: Components | K89: CMP-2854 | L89: 601.51 | M89: 679.35 | N89: 0.188 | O89: 3
...

Sheet Working Sheet
A1: OrderID | B1: OrderDate | C1: RequiredDate | D1: CorrectedRequiredDate | E1: LeadTimeDays | F1: CorrectedLeadTimeDays | G1: OnTimeFlag | H1: MonthOrderDate | I1: Quarter | J1: FirstYearMonth | K1: CountryFirstMonth | L1: Region | M1: Country | N1: City | O1: CustomerSegment | P1: Channel | Q1: Salesperson | R1: MonthsSinceFirstSale | S1: ProductCategory | T1: SKU | U1: UnitCost | V1: ScenarioUnitCost | W1: CostofGoods | X1: ScenarioCostOfGoods | Y1: UnitPrice | Z1: GrossRevenue | AA1: ScenarioRev | AB1: GrossProfit | AC1: ScenarioProfit | AD1: DiscountPct | AE1: ScenarioDiscPct | AF1: HighDiscPct | AG1: Priceband | AH1: MarginPct | AI1: Quantity | AJ1: ScenarioQuanity
A2: ORD-2025-874124 | B2: 45791 | C2: 45789 | D2: =IF(C2<B2, B2+14, C2) -> 45805 | E2: =C2-B2 -> -2 | F2: =D2-B2 -> 14 | G2: =IF(Table1[[#This Row],[CorrectedLeadTimeDays]]<=7, 1, 0) -> 0 | H2: =TEXT(B2, "mmmm") -> May | I2: ="Q"&ROUNDUP(MONTH(B2)/3,0)&"-"&YEAR(B2) -> Q2-2025 | J2: =TEXT(K2, "yyyy-mm") -> 2023-01 | K2: =_xlfn.MINIFS($B:$B,$M:$M,M2) -> 44928 | L2: Americas | M2: Canada | N2: Vancouver | O2: Non-Profit | P2: Distributor | Q2: F. Müller | R2: =DATEDIF(K2,B2,"m") -> 28 | S2: Printers | T2: PRN-2407 | U2: 883.5 | V2: =Table1[[#This Row],[UnitCost]]*(1+WhatIf!$B$3) -> 927.675 | W2: =U2*AI2 -> 23854.5 | X2: =Table1[[#This Row],[ScenarioRev]]-Table1[[#This Row],[ScenarioUnitCost]] -> 54672.176 | Y2: 1978.91 | Z2: =Y2*AI2*(1-AD2) -> 50545.319 | AA2: =Table1[[#This Row],[ScenarioQuanity]]*Table1[[#This Row],[UnitPrice]]*(1-Table1[[#This Row],[ScenarioDiscPct]]) -> 55599.851 | AB2: =Z2-W2 -> 26690.819 | AC2: =Table1[[#This Row],[ScenarioRev]] - Table1[[#This Row],[ScenarioCostOfGoods]] -> 927.675 | AD2: 0.054 | AE2: =MIN(Table1[[#This Row],[DiscountPct]], WhatIf!$B$2) -> 0.054 | AF2: =IF(Table1[[#This Row],[DiscountPct]]>0.2, 1, 0) -> 0 | AG2: =IF(Y2<=_xlfn.PERCENTILE.INC($Y:$Y,0.33),"Low", IF(D2<=_xlfn.PERCENTILE.INC($Y:$Y,0.66),"Medium", "High")) -> High | AH2: =IF(Z2=0, 0, AB2/Z2) -> 0.52805719 | AI2: 27 | AJ2: =Table1[[#This Row],[Quantity]]*(1+WhatIf!$B$4) -> 29.7
A3: ORD-2024-585443 | B3: 45521 | C3: 45519 | D3: =IF(C3<B3, B3+14, C3) -> 45535 | E3: =C3-B3 -> -2 | F3: =D3-B3 -> 14 | G3: =IF(Table1[[#This Row],[CorrectedLeadTimeDays]]<=7, 1, 0) -> 0 | H3: =TEXT(B3, "mmmm") -> August | I3: ="Q"&ROUNDUP(MONTH(B3)/3,0)&"-"&YEAR(B3) -> Q3-2024 | J3: =TEXT(K3, "yyyy-mm") -> 2023-01 | K3: =_xlfn.MINIFS($B:$B,$M:$M,M3) -> 44955 | L3: Americas | M3: Brazil | N3: Rio de Janeiro | O3: Consumer | P3: Direct | Q3: M. Rossi | R3: =DATEDIF(K3,B3,"m") -> 18 | S3: Monitors | T3: MON-2849 | U3: 165.3 | V3: =Table1[[#This Row],[UnitCost]]*(1+WhatIf!$B$3) -> 173.565 | W3: =U3*AI3 -> 4132.5 | X3: =Table1[[#This Row],[ScenarioRev]]-Table1[[#This Row],[ScenarioUnitCost]] -> 6384.7915 | Y3: 275.07 | Z3: =Y3*AI3*(1-AD3) -> 5962.1422 | AA3: =Table1[[#This Row],[ScenarioQuanity]]*Table1[[#This Row],[UnitPrice]]*(1-Table1[[#This Row],[ScenarioDiscPct]]) -> 6558.3565 | AB3: =Z3-W3 -> 1829.6422 | AC3: =Table1[[#This Row],[ScenarioRev]] - Table1[[#This Row],[ScenarioCostOfGoods]] -> 173.565 | AD3: 0.133 | AE3: =MIN(Table1[[#This Row],[DiscountPct]], WhatIf!$B$2) -> 0.133 | AF3: =IF(Table1[[#This Row],[DiscountPct]]>0.2, 1, 0) -> 0 | AG3: =IF(Y3<=_xlfn.PERCENTILE.INC($Y:$Y,0.33),"Low", IF(D3<=_xlfn.PERCENTILE.INC($Y:$Y,0.66),"Medium", "High")) -> Low | AH3: =IF(Z3=0, 0, AB3/Z3) -> 0.30687665 | AI3: 25 | AJ3: =Table1[[#This Row],[Quantity]]*(1+WhatIf!$B$4) -> 27.5
A4: ORD-2023-766015 | B4: 45029 | C4: 45027 | D4: =IF(C4<B4, B4+14, C4) -> 45043 | E4: =C4-B4 -> -2 | F4: =D4-B4 -> 14 | G4: =IF(Table1[[#This Row],[CorrectedLeadTimeDays]]<=7, 1, 0) -> 0 | H4: =TEXT(B4, "mmmm") -> April | I4: ="Q"&ROUNDUP(MONTH(B4)/3,0)&"-"&YEAR(B4) -> Q2-2023 | J4: =TEXT(K4, "yyyy-mm") -> 2023-01 | K4: =_xlfn.MINIFS($B:$B,$M:$M,M4) -> 44939 | L4: Americas | M4: USA | N4: San Francisco | O4: Education | P4: Marketplace | Q4: G. Dubois | R4: =DATEDIF(K4,B4,"m") -> 3 | S4: Networking | T4: NET-1816 | U4: 32.1 | V4: =Table1[[#This Row],[UnitCost]]*(1+WhatIf!$B$3) -> 33.705 | W4: =U4*AI4 -> 706.2 | X4: =Table1[[#This Row],[ScenarioRev]]-Table1[[#This Row],[ScenarioUnitCost]] -> 1333.111 | Y4: 70.6 | Z4: =Y4*AI4*(1-AD4) -> 1115.1976 | AA4: =Table1[[#This Row],[ScenarioQuanity]]*Table1[[#This Row],[UnitPrice]]*(1-Table1[[#This Row],[ScenarioDiscPct]]) -> 1366.816 | AB4: =Z4-W4 -> 408.9976 | AC4: =Table1[[#This Row],[ScenarioRev]] - Table1[[#This Row],[ScenarioCostOfGoods]] -> 33.705 | AD4: 0.282 | AE4: =MIN(Table1[[#This Row],[DiscountPct]], WhatIf!$B$2) -> 0.2 | AF4: =IF(Table1[[#This Row],[DiscountPct]]>0.2, 1, 0) -> 1 | AG4: =IF(Y4<=_xlfn.PERCENTILE.INC($Y:$Y,0.33),"Low", IF(D4<=_xlfn.PERCENTILE.INC($Y:$Y,0.66),"Medium", "High")) -> Low | AH4: =IF(Z4=0, 0, AB4/Z4) -> 0.366749 | AI4: 22 | AJ4: =Table1[[#This Row],[Quantity]]*(1+WhatIf!$B$4) -> 24.2
A5: ORD-2024-594527 | B5: 45541 | C5: 45539 | D5: =IF(C5<B5, B5+14, C5) -> 45555 | E5: =C5-B5 -> -2 | F5: =D5-B5 -> 14 | G5: =IF(Table1[[#This Row],[CorrectedLeadTimeDays]]<=7, 1, 0) -> 0 | H5: =TEXT(B5, "mmmm") -> September | I5: ="Q"&ROUNDUP(MONTH(B5)/3,0)&"-"&YEAR(B5) -> Q3-2024 | J5: =TEXT(K5, "yyyy-mm") -> 2023-03 | K5: =_xlfn.MINIFS($B:$B,$M:$M,M5) -> 44988 | L5: Asia | M5: Japan | N5: Osaka | O5: Corporate | P5: Direct | Q5: A. Patel | R5: =DATEDIF(K5,B5,"m") -> 18 | S5: Laptops | T5: LAP-4483 | U5: 1368.17 | V5: =Table1[[#This Row],[UnitCost]]*(1+WhatIf!$B$3) -> 1436.5785 | W5: =U5*AI5 -> 28731.57 | X5: =Table1[[#This Row],[ScenarioRev]]-Table1[[#This Row],[ScenarioUnitCost]] -> 43183.075 | Y5: 2307.75 | Z5: =Y5*AI5*(1-AD5) -> 40563.322 | AA5: =Table1[[#This Row],[ScenarioQuanity]]*Table1[[#This Row],[UnitPrice]]*(1-Table1[[#This Row],[ScenarioDiscPct]]) -> 44619.654 | AB5: =Z5-W5 -> 11831.752 | AC5: =Table1[[#This Row],[ScenarioRev]] - Table1[[#This Row],[ScenarioCostOfGoods]] -> 1436.5785 | AD5: 0.163 | AE5: =MIN(Table1[[#This Row],[DiscountPct]], WhatIf!$B$2) -> 0.163 | AF5: =IF(Table1[[#This Row],[DiscountPct]]>0.2, 1, 0) -> 0 | AG5: =IF(Y5<=_xlfn.PERCENTILE.INC($Y:$Y,0.33),"Low", IF(D5<=_xlfn.PERCENTILE.INC($Y:$Y,0.66),"Medium", "High")) -> High | AH5: =IF(Z5=0, 0, AB5/Z5) -> 0.29168597 | AI5: 21 | AJ5: =Table1[[#This Row],[Quantity]]*(1+WhatIf!$B$4) -> 23.1
A6: ORD-2025-745263 | B6: 45798 | C6: 45796 | D6: =IF(C6<B6, B6+14, C6) -> 45812 | E6: =C6-B6 -> -2 | F6: =D6-B6 -> 14 | G6: =IF(Table1[[#This Row],[CorrectedLeadTimeDays]]<=7, 1, 0) -> 0 | H6: =TEXT(B6, "mmmm") -> May | I6: ="Q"&ROUNDUP(MONTH(B6)/3,0)&"-"&YEAR(B6) -> Q2-2025 | J6: =TEXT(K6, "yyyy-mm") -> 2023-01 | K6: =_xlfn.MINIFS($B:$B,$M:$M,M6) -> 44945 | L6: Europe | M6: United Kingdom | N6: Birmingham | O6: Enterprise | P6: Online | Q6: M. Rossi | R6: =DATEDIF(K6,B6,"m") -> 28 | S6: Laptops | T6: LAP-3385 | U6: 1015.16 | V6: =Table1[[#This Row],[UnitCost]]*(1+WhatIf!$B$3) -> 1065.918 | W6: =U6*AI6 -> 19288.04 | X6: =Table1[[#This Row],[ScenarioRev]]-Table1[[#This Row],[ScenarioUnitCost]] -> 42124.155 | Y6: 2148.14 | Z6: =Y6*AI6*(1-AD6) -> 39263.703 | AA6: =Table1[[#This Row],[ScenarioQuanity]]*Table1[[#This Row],[UnitPrice]]*(1-Table1[[#This Row],[ScenarioDiscPct]]) -> 43190.073 | AB6: =Z6-W6 -> 19975.663 | AC6: =Table1[[#This Row],[ScenarioRev]] - Table1[[#This Row],[ScenarioCostOfGoods]] -> 1065.918 | AD6: 0.038 | AE6: =MIN(Table1[[#This Row],[DiscountPct]], WhatIf!$B$2) -> 0.038 | AF6: =IF(Table1[[#This Row],[DiscountPct]]>0.2, 1, 0) -> 0 | AG6: =IF(Y6<=_xlfn.PERCENTILE.INC($Y:$Y,0.33),"Low", IF(D6<=_xlfn.PERCENTILE.INC($Y:$Y,0.66),"Medium", "High")) -> High | AH6: =IF(Z6=0, 0, AB6/Z6) -> 0.50875647 | AI6: 19 | AJ6: =Table1[[#This Row],[Quantity]]*(1+WhatIf!$B$4) -> 20.9
A7: ORD-2024-638884 | B7: 45440 | C7: 45438 | D7: =IF(C7<B7, B7+14, C7) -> 45454 | E7: =C7-B7 -> -2 | F7: =D7-B7 -> 14 | G7: =IF(Table1[[#This Row],[CorrectedLeadTimeDays]]<=7, 1, 0) -> 0 | H7: =TEXT(B7, "mmmm") -> May | I7: ="Q"&ROUNDUP(MONTH(B7)/3,0)&"-"&YEAR(B7) -> Q2-2024 | J7: =TEXT(K7, "yyyy-mm") -> 2023-01 | K7: =_xlfn.MINIFS($B:$B,$M:$M,M7) -> 44941 | L7: Africa | M7: Nigeria | N7: Abuja | O7: Enterprise | P7: Online | Q7: F. Müller | R7: =DATEDIF(K7,B7,"m") -> 16 | S7: Accessories | T7: ACC-5177 | U7: 1227.08 | V7: =Table1[[#This Row],[UnitCost]]*(1+WhatIf!$B$3) -> 1288.434 | W7: =U7*AI7 -> 22087.44 | X7: =Table1[[#This Row],[ScenarioRev]]-Table1[[#This Row],[ScenarioUnitCost]] -> 36264.642 | Y7: 1896.62 | Z7: =Y7*AI7*(1-AD7) -> 34139.16 | AA7: =Table1[[#This Row],[ScenarioQuanity]]*Table1[[#This Row],[UnitPrice]]*(1-Table1[[#This Row],[ScenarioDiscPct]]) -> 37553.076 | AB7: =Z7-W7 -> 12051.72 | AC7: =Table1[[#This Row],[ScenarioRev]] - Table1[[#This Row],[ScenarioCostOfGoods]] -> 1288.434 | AD7: 0 | AE7: =MIN(Table1[[#This Row],[DiscountPct]], WhatIf!$B$2) -> 0 | AF7: =IF(Table1[[#This Row],[DiscountPct]]>0.2, 1, 0) -> 0 | AG7: =IF(Y7<=_xlfn.PERCENTILE.INC($Y:$Y,0.33),"Low", IF(D7<=_xlfn.PERCENTILE.INC($Y:$Y,0.66),"Medium", "High")) -> High | AH7: =IF(Z7=0, 0, AB7/Z7) -> 0.35301747 | AI7: 18 | AJ7: =Table1[[#This Row],[Quantity]]*(1+WhatIf!$B$4) -> 19.8
A8: ORD-2025-922513 | B8: 45897 | C8: 45895 | D8: =IF(C8<B8, B8+14, C8) -> 45911 | E8: =C8-B8 -> -2 | F8: =D8-B8 -> 14 | G8: =IF(Table1[[#This Row],[CorrectedLeadTimeDays]]<=7, 1, 0) -> 0 | H8: =TEXT(B8, "mmmm") -> August | I8: ="Q"&ROUNDUP(MONTH(B8)/3,0)&"-"&YEAR(B8) -> Q3-2025 | J8: =TEXT(K8, "yyyy-mm") -> 2023-01 | K8: =_xlfn.MINIFS($B:$B,$M:$M,M8) -> 44941 | L8: Africa | M8: Nigeria | N8: Port Harcourt | O8: Small Business | P8: Retail | Q8: A. Patel | R8: =DATEDIF(K8,B8,"m") -> 31 | S8: Accessories | T8: ACC-4483 | U8: 521.06 | V8: =Table1[[#This Row],[UnitCost]]*(1+WhatIf!$B$3) -> 547.113 | W8: =U8*AI8 -> 9379.08 | X8: =Table1[[#This Row],[ScenarioRev]]-Table1[[#This Row],[ScenarioUnitCost]] -> 20425.537 | Y8: 1240.31 | Z8: =Y8*AI8*(1-AD8) -> 19066.045 | AA8: =Table1[[#This Row],[ScenarioQuanity]]*Table1[[#This Row],[UnitPrice]]*(1-Table1[[#This Row],[ScenarioDiscPct]]) -> 20972.65 | AB8: =Z8-W8 -> 9686.9653 | AC8: =Table1[[#This Row],[ScenarioRev]] - Table1[[#This Row],[ScenarioCostOfGoods]] -> 547.113 | AD8: 0.146 | AE8: =MIN(Table1[[#This Row],[DiscountPct]], WhatIf!$B$2) -> 0.146 | AF8: =IF(Table1[[#This Row],[DiscountPct]]>0.2, 1, 0) -> 0 | AG8: =IF(Y8<=_xlfn.PERCENTILE.INC($Y:$Y,0.33),"Low", IF(D8<=_xlfn.PERCENTILE.INC($Y:$Y,0.66),"Medium", "High")) -> High | AH8: =IF(Z8=0, 0, AB8/Z8) -> 0.50807418 | AI8: 18 | AJ8: =Table1[[#This Row],[Quantity]]*(1+WhatIf!$B$4) -> 19.8
A9: ORD-2023-112666 | B9: 44941 | C9: 44939 | D9: =IF(C9<B9, B9+14, C9) -> 44955 | E9: =C9-B9 -> -2 | F9: =D9-B9 -> 14 | G9: =IF(Table1[[#This Row],[CorrectedLeadTimeDays]]<=7, 1, 0) -> 0 | H9: =TEXT(B9, "mmmm") -> January | I9: ="Q"&ROUNDUP(MONTH(B9)/3,0)&"-"&YEAR(B9) -> Q1-2023 | J9: =TEXT(K9, "yyyy-mm") -> 2023-01 | K9: =_xlfn.MINIFS($B:$B,$M:$M,M9) -> 44941 | L9: Africa | M9: Nigeria | N9: Abuja | O9: Education | P9: Online | Q9: O. Wang | R9: =DATEDIF(K9,B9,"m") -> 0 | S9: Printers | T9: PRN-6276 | U9: 28.38 | V9: =Table1[[#This Row],[UnitCost]]*(1+WhatIf!$B$3) -> 29.799 | W9: =U9*AI9 -> 510.84 | X9: =Table1[[#This Row],[ScenarioRev]]-Table1[[#This Row],[ScenarioUnitCost]] -> 723.77554 | Y9: 47.22 | Z9: =Y9*AI9*(1-AD9) -> 685.06776 | AA9: =Table1[[#This Row],[ScenarioQuanity]]*Table1[[#This Row],[UnitPrice]]*(1-Table1[[#This Row],[ScenarioDiscPct]]) -> 753.57454 | AB9: =Z9-W9 -> 174.22776 | AC9: =Table1[[#This Row],[ScenarioRev]] - Table1[[#This Row],[ScenarioCostOfGoods]] -> 29.799 | AD9: 0.194 | AE9: =MIN(Table1[[#This Row],[DiscountPct]], WhatIf!$B$2) -> 0.194 | AF9: =IF(Table1[[#This Row],[DiscountPct]]>0.2, 1, 0) -> 0 | AG9: =IF(Y9<=_xlfn.PERCENTILE.INC($Y:$Y,0.33),"Low", IF(D9<=_xlfn.PERCENTILE.INC($Y:$Y,0.66),"Medium", "High")) -> Low | AH9: =IF(Z9=0, 0, AB9/Z9) -> 0.25432194 | AI9: 18 | AJ9: =Table1[[#This Row],[Quantity]]*(1+WhatIf!$B$4) -> 19.8
A10: ORD-2024-451005 | B10: 45473 | C10: 45471 | D10: =IF(C10<B10, B10+14, C10) -> 45487 | E10: =C10-B10 -> -2 | F10: =D10-B10 -> 14 | G10: =IF(Table1[[#This Row],[CorrectedLeadTimeDays]]<=7, 1, 0) -> 0 | H10: =TEXT(B10, "mmmm") -> June | I10: ="Q"&ROUNDUP(MONTH(B10)/3,0)&"-"&YEAR(B10) -> Q2-2024 | J10: =TEXT(K10, "yyyy-mm") -> 2023-01 | K10: =_xlfn.MINIFS($B:$B,$M:$M,M10) -> 44955 | L10: Americas | M10: Brazil | N10: Rio de Janeiro | O10: Small Business | P10: Direct | Q10: L. Okafor | R10: =DATEDIF(K10,B10,"m") -> 17 | S10: Accessories | T10: ACC-9162 | U10: 1112.98 | V10: =Table1[[#This Row],[UnitCost]]*(1+WhatIf!$B$3) -> 1168.629 | W10: =U10*AI10 -> 18920.66 | X10: =Table1[[#This Row],[ScenarioRev]]-Table1[[#This Row],[ScenarioUnitCost]] -> 35199.831 | Y10: 2095.73 | Z10: =Y10*AI10*(1-AD10) -> 33062.236 | AA10: =Table1[[#This Row],[ScenarioQuanity]]*Table1[[#This Row],[UnitPrice]]*(1-Table1[[#This Row],[ScenarioDiscPct]]) -> 36368.46 | AB10: =Z10-W10 -> 14141.576 | AC10: =Table1[[#This Row],[ScenarioRev]] - Table1[[#This Row],[ScenarioCostOfGoods]] -> 1168.629 | AD10: 0.072 | AE10: =MIN(Table1[[#This Row],[DiscountPct]], WhatIf!$B$2) -> 0.072 | AF10: =IF(Table1[[#This Row],[DiscountPct]]>0.2, 1, 0) -> 0 | AG10: =IF(Y10<=_xlfn.PERCENTILE.INC($Y:$Y,0.33),"Low", IF(D10<=_xlfn.PERCENTILE.INC($Y:$Y,0.66),"Medium", "High")) -> High | AH10: =IF(Z10=0, 0, AB10/Z10) -> 0.42772595 | AI10: 17 | AJ10: =Table1[[#This Row],[Quantity]]*(1+WhatIf!$B$4) -> 18.7
A11: ORD-2025-700847 | B11: 45798 | C11: 45796 | D11: =IF(C11<B11, B11+14, C11) -> 45812 | E11: =C11-B11 -> -2 | F11: =D11-B11 -> 14 | G11: =IF(Table1[[#This Row],[CorrectedLeadTimeDays]]<=7, 1, 0) -> 0 | H11: =TEXT(B11, "mmmm") -> May | I11: ="Q"&ROUNDUP(MONTH(B11)/3,0)&"-"&YEAR(B11) -> Q2-2025 | J11: =TEXT(K11, "yyyy-mm") -> 2023-01 | K11: =_xlfn.MINIFS($B:$B,$M:$M,M11) -> 44933 | L11: Africa | M11: South Africa | N11: Johannesburg | O11: Non-Profit | P11: Distributor | Q11: O. Wang | R11: =DATEDIF(K11,B11,"m") -> 28 | S11: Laptops | T11: LAP-7099 | U11: 1263.84 | V11: =Table1[[#This Row],[UnitCost]]*(1+WhatIf!$B$3) -> 1327.032 | W11: =U11*AI11 -> 18957.6 | X11: =Table1[[#This Row],[ScenarioRev]]-Table1[[#This Row],[ScenarioUnitCost]] -> 33384.774 | Y11: 2281.72 | Z11: =Y11*AI11*(1-AD11) -> 31556.188 | AA11: =Table1[[#This Row],[ScenarioQuanity]]*Table1[[#This Row],[UnitPrice]]*(1-Table1[[#This Row],[ScenarioDiscPct]]) -> 34711.806 | AB11: =Z11-W11 -> 12598.588 | AC11: =Table1[[#This Row],[ScenarioRev]] - Table1[[#This Row],[ScenarioCostOfGoods]] -> 1327.032 | AD11: 0.078 | AE11: =MIN(Table1[[#This Row],[DiscountPct]], WhatIf!$B$2) -> 0.078 | AF11: =IF(Table1[[#This Row],[DiscountPct]]>0.2, 1, 0) -> 0 | AG11: =IF(Y11<=_xlfn.PERCENTILE.INC($Y:$Y,0.33),"Low", IF(D11<=_xlfn.PERCENTILE.INC($Y:$Y,0.66),"Medium", "High")) -> High | AH11: =IF(Z11=0, 0, AB11/Z11) -> 0.39924302 | AI11: 15 | AJ11: =Table1[[#This Row],[Quantity]]*(1+WhatIf!$B$4) -> 16.5
A12: ORD-2023-890605 | B12: 45101 | C12: 45099 | D12: =IF(C12<B12, B12+14, C12) -> 45115 | E12: =C12-B12 -> -2 | F12: =D12-B12 -> 14 | G12: =IF(Table1[[#This Row],[CorrectedLeadTimeDays]]<=7, 1, 0) -> 0 | H12: =TEXT(B12, "mmmm") -> June | I12: ="Q"&ROUNDUP(MONTH(B12)/3,0)&"-"&YEAR(B12) -> Q2-2023 | J12: =TEXT(K12, "yyyy-mm") -> 2023-01 | K12: =_xlfn.MINIFS($B:$B,$M:$M,M12) -> 44928 | L12: Americas | M12: Canada | N12: Toronto | O12: Non-Profit | P12: Retail | Q12: M. Rossi | R12: =DATEDIF(K12,B12,"m") -> 5 | S12: Accessories | T12: ACC-2903 | U12: 471.42 | V12: =Table1[[#This Row],[UnitCost]]*(1+WhatIf!$B$3) -> 494.991 | W12: =U12*AI12 -> 7071.3 | X12: =Table1[[#This Row],[ScenarioRev]]-Table1[[#This Row],[ScenarioUnitCost]] -> 11916.75 | Y12: 824.81 | Z12: =Y12*AI12*(1-AD12) -> 11283.401 | AA12: =Table1[[#This Row],[ScenarioQuanity]]*Table1[[#This Row],[UnitPrice]]*(1-Table1[[#This Row],[ScenarioDiscPct]]) -> 12411.741 | AB12: =Z12-W12 -> 4212.1008 | AC12: =Table1[[#This Row],[ScenarioRev]] - Table1[[#This Row],[ScenarioCostOfGoods]] -> 494.991 | AD12: 0.088 | AE12: =MIN(Table1[[#This Row],[DiscountPct]], WhatIf!$B$2) -> 0.088 | AF12: =IF(Table1[[#This Row],[DiscountPct]]>0.2, 1, 0) -> 0 | AG12: =IF(Y12<=_xlfn.PERCENTILE.INC($Y:$Y,0.33),"Low", IF(D12<=_xlfn.PERCENTILE.INC($Y:$Y,0.66),"Medium", "High")) -> High | AH12: =IF(Z12=0, 0, AB12/Z12) -> 0.37330065 | AI12: 15 | AJ12: =Table1[[#This Row],[Quantity]]*(1+WhatIf!$B$4) -> 16.5
A13: ORD-2024-567435 | B13: 45408 | C13: 45406 | D13: =IF(C13<B13, B13+14, C13) -> 45422 | E13: =C13-B13 -> -2 | F13: =D13-B13 -> 14 | G13: =IF(Table1[[#This Row],[CorrectedLeadTimeDays]]<=7, 1, 0) -> 0 | H13: =TEXT(B13, "mmmm") -> April | I13: ="Q"&ROUNDUP(MONTH(B13)/3,0)&"-"&YEAR(B13) -> Q2-2024 | J13: =TEXT(K13, "yyyy-mm") -> 2023-01 | K13: =_xlfn.MINIFS($B:$B,$M:$M,M13) -> 44945 | L13: Europe | M13: United Kingdom | N13: London | O13: Non-Profit | P13: Distributor | Q13: N. Brown | R13: =DATEDIF(K13,B13,"m") -> 15 | S13: Phones | T13: PHN-9107 | U13: 1232.77 | V13: =Table1[[#This Row],[UnitCost]]*(1+WhatIf!$B$3) -> 1294.4085 | W13: =U13*AI13 -> 12327.7 | X13: =Table1[[#This Row],[ScenarioRev]]-Table1[[#This Row],[ScenarioUnitCost]] -> 6876.5135 | Y13: 891.73 | Z13: =Y13*AI13*(1-AD13) -> 7428.1109 | AA13: =Table1[[#This Row],[ScenarioQuanity]]*Table1[[#This Row],[UnitPrice]]*(1-Table1[[#This Row],[ScenarioDiscPct]]) -> 8170.922 | AB13: =Z13-W13 -> -4899.5891 | AC13: =Table1[[#This Row],[ScenarioRev]] - Table1[[#This Row],[ScenarioCostOfGoods]] -> 1294.4085 | AD13: 0.167 | AE13: =MIN(Table1[[#This Row],[DiscountPct]], WhatIf!$B$2) -> 0.167 | AF13: =IF(Table1[[#This Row],[DiscountPct]]>0.2, 1, 0) -> 0 | AG13: =IF(Y13<=_xlfn.PERCENTILE.INC($Y:$Y,0.33),"Low", IF(D13<=_xlfn.PERCENTILE.INC($Y:$Y,0.66),"Medium", "High")) -> High | AH13: =IF(Z13=0, 0, AB13/Z13) -> -0.65960096 | AI13: 10 | AJ13: =Table1[[#This Row],[Quantity]]*(1+WhatIf!$B$4) -> 11
... A79: ORD-2024-301260 | B79: 45502 | C79: 45504 | D79: =IF(C79<B79, B79+14, C79) -> 45504 | E79: =C79-B79 -> 2 | F79: =D79-B79 -> 2 | G79: =IF(Table1[[#This Row],[CorrectedLeadTimeDays]]<=7, 1, 0) -> 1 | H79: =TEXT(B79, "mmmm") -> July | I79: ="Q"&ROUNDUP(MONTH(B79)/3,0)&"-"&YEAR(B79) -> Q3-2024 | J79: =TEXT(K79, "yyyy-mm") -> 2023-01 | K79: =_xlfn.MINIFS($B:$B,$M:$M,M79) -> 44939 | L79: Americas | M79: USA | N79: New York | O79: Education | P79: Marketplace | Q79: I. Johnson | R79: =DATEDIF(K79,B79,"m") -> 18 | S79: Printers | T79: PRN-2829 | U79: 798.97 | V79: =Table1[[#This Row],[UnitCost]]*(1+WhatIf!$B$3) -> 838.9185 | W79: =U79*AI79 -> 12783.52 | X79: =Table1[[#This Row],[ScenarioRev]]-Table1[[#This Row],[ScenarioUnitCost]] -> 27193.388 | Y79: 1814.06 | Z79: =Y79*AI79*(1-AD79) -> 25483.915 | AA79: =Table1[[#This Row],[ScenarioQuanity]]*Table1[[#This Row],[UnitPrice]]*(1-Table1[[#This Row],[ScenarioDiscPct]]) -> 28032.306 | AB79: =Z79-W79 -> 12700.395 | AC79: =Table1[[#This Row],[ScenarioRev]] - Table1[[#This Row],[ScenarioCostOfGoods]] -> 838.9185 | AD79: 0.122 | AE79: =MIN(Table1[[#This Row],[DiscountPct]], WhatIf!$B$2) -> 0.122 | AF79: =IF(Table1[[#This Row],[DiscountPct]]>0.2, 1, 0) -> 0 | AG79: =IF(Y79<=_xlfn.PERCENTILE.INC($Y:$Y,0.33),"Low", IF(D79<=_xlfn.PERCENTILE.INC($Y:$Y,0.66),"Medium", "High")) -> High | AH79: =IF(Z79=0, 0, AB79/Z79) -> 0.49836907 | AI79: 16 | AJ79: =Table1[[#This Row],[Quantity]]*(1+WhatIf!$B$4) -> 17.6
A80: ORD-2023-888140 | B80: 45210 | C80: 45212 | D80: =IF(C80<B80, B80+14, C80) -> 45212 | E80: =C80-B80 -> 2 | F80: =D80-B80 -> 2 | G80: =IF(Table1[[#This Row],[CorrectedLeadTimeDays]]<=7, 1, 0) -> 1 | H80: =TEXT(B80, "mmmm") -> October | I80: ="Q"&ROUNDUP(MONTH(B80)/3,0)&"-"&YEAR(B80) -> Q4-2023 | J80: =TEXT(K80, "yyyy-mm") -> 2023-01 | K80: =_xlfn.MINIFS($B:$B,$M:$M,M80) -> 44955 | L80: Americas | M80: Brazil | N80: Brasília | O80: Consumer | P80: Distributor | R80: =DATEDIF(K80,B80,"m") -> 8 | S80: Accessories | T80: ACC-3567 | U80: 715.94 | V80: =Table1[[#This Row],[UnitCost]]*(1+WhatIf!$B$3) -> 751.737 | W80: =U80*AI80 -> 11455.04 | X80: =Table1[[#This Row],[ScenarioRev]]-Table1[[#This Row],[ScenarioUnitCost]] -> 7574.1225 | Y80: 550.07 | Z80: =Y80*AI80*(1-AD80) -> 7568.9632 | AA80: =Table1[[#This Row],[ScenarioQuanity]]*Table1[[#This Row],[UnitPrice]]*(1-Table1[[#This Row],[ScenarioDiscPct]]) -> 8325.8595 | AB80: =Z80-W80 -> -3886.0768 | AC80: =Table1[[#This Row],[ScenarioRev]] - Table1[[#This Row],[ScenarioCostOfGoods]] -> 751.737 | AD80: 0.14 | AE80: =MIN(Table1[[#This Row],[DiscountPct]], WhatIf!$B$2) -> 0.14 | AF80: =IF(Table1[[#This Row],[DiscountPct]]>0.2, 1, 0) -> 0 | AG80: =IF(Y80<=_xlfn.PERCENTILE.INC($Y:$Y,0.33),"Low", IF(D80<=_xlfn.PERCENTILE.INC($Y:$Y,0.66),"Medium", "High")) -> Low | AH80: =IF(Z80=0, 0, AB80/Z80) -> -0.5134226 | AI80: 16 | AJ80: =Table1[[#This Row],[Quantity]]*(1+WhatIf!$B$4) -> 17.6
A81: ORD-2025-779574 | B81: 45910 | C81: 45912 | D81: =IF(C81<B81, B81+14, C81) -> 45912 | E81: =C81-B81 -> 2 | F81: =D81-B81 -> 2 | G81: =IF(Table1[[#This Row],[CorrectedLeadTimeDays]]<=7, 1, 0) -> 1 | H81: =TEXT(B81, "mmmm") -> September | I81: ="Q"&ROUNDUP(MONTH(B81)/3,0)&"-"&YEAR(B81) -> Q3-2025 | J81: =TEXT(K81, "yyyy-mm") -> 2023-03 | K81: =_xlfn.MINIFS($B:$B,$M:$M,M81) -> 44988 | L81: Asia | M81: Japan | N81: Tokyo | O81: Consumer | P81: Online | Q81: O. Wang | R81: =DATEDIF(K81,B81,"m") -> 30 | S81: Components | T81: CMP-6971 | U81: 1470.15 | V81: =Table1[[#This Row],[UnitCost]]*(1+WhatIf!$B$3) -> 1543.6575 | W81: =U81*AI81 -> 17641.8 | X81: =Table1[[#This Row],[ScenarioRev]]-Table1[[#This Row],[ScenarioUnitCost]] -> 28928.07 | Y81: 2593.78 | Z81: =Y81*AI81*(1-AD81) -> 27701.57 | AA81: =Table1[[#This Row],[ScenarioQuanity]]*Table1[[#This Row],[UnitPrice]]*(1-Table1[[#This Row],[ScenarioDiscPct]]) -> 30471.727 | AB81: =Z81-W81 -> 10059.77 | AC81: =Table1[[#This Row],[ScenarioRev]] - Table1[[#This Row],[ScenarioCostOfGoods]] -> 1543.6575 | AD81: 0.11 | AE81: =MIN(Table1[[#This Row],[DiscountPct]], WhatIf!$B$2) -> 0.11 | AF81: =IF(Table1[[#This Row],[DiscountPct]]>0.2, 1, 0) -> 0 | AG81: =IF(Y81<=_xlfn.PERCENTILE.INC($Y:$Y,0.33),"Low", IF(D81<=_xlfn.PERCENTILE.INC($Y:$Y,0.66),"Medium", "High")) -> High | AH81: =IF(Z81=0, 0, AB81/Z81) -> 0.36314802 | AI81: 12 | AJ81: =Table1[[#This Row],[Quantity]]*(1+WhatIf!$B$4) -> 13.2
A82: ORD-2023-502205 | B82: 45208 | C82: 45210 | D82: =IF(C82<B82, B82+14, C82) -> 45210 | E82: =C82-B82 -> 2 | F82: =D82-B82 -> 2 | G82: =IF(Table1[[#This Row],[CorrectedLeadTimeDays]]<=7, 1, 0) -> 1 | H82: =TEXT(B82, "mmmm") -> October | I82: ="Q"&ROUNDUP(MONTH(B82)/3,0)&"-"&YEAR(B82) -> Q4-2023 | J82: =TEXT(K82, "yyyy-mm") -> 2023-01 | K82: =_xlfn.MINIFS($B:$B,$M:$M,M82) -> 44941 | L82: Africa | M82: Nigeria | N82: Port Harcourt | O82: Education | P82: Marketplace | Q82: K. Singh | R82: =DATEDIF(K82,B82,"m") -> 8 | S82: Networking | T82: NET-8856 | U82: 391.16 | V82: =Table1[[#This Row],[UnitCost]]*(1+WhatIf!$B$3) -> 410.718 | W82: =U82*AI82 -> 4693.92 | X82: =Table1[[#This Row],[ScenarioRev]]-Table1[[#This Row],[ScenarioUnitCost]] -> 11454.236 | Y82: 902.47 | Z82: =Y82*AI82*(1-AD82) -> 10786.321 | AA82: =Table1[[#This Row],[ScenarioQuanity]]*Table1[[#This Row],[UnitPrice]]*(1-Table1[[#This Row],[ScenarioDiscPct]]) -> 11864.954 | AB82: =Z82-W82 -> 6092.4014 | AC82: =Table1[[#This Row],[ScenarioRev]] - Table1[[#This Row],[ScenarioCostOfGoods]] -> 410.718 | AD82: 0.004 | AE82: =MIN(Table1[[#This Row],[DiscountPct]], WhatIf!$B$2) -> 0.004 | AF82: =IF(Table1[[#This Row],[DiscountPct]]>0.2, 1, 0) -> 0 | AG82: =IF(Y82<=_xlfn.PERCENTILE.INC($Y:$Y,0.33),"Low", IF(D82<=_xlfn.PERCENTILE.INC($Y:$Y,0.66),"Medium", "High")) -> High | AH82: =IF(Z82=0, 0, AB82/Z82) -> 0.56482662 | AI82: 12 | AJ82: =Table1[[#This Row],[Quantity]]*(1+WhatIf!$B$4) -> 13.2
A83: ORD-2023-842488 | B83: 45230 | C83: 45232 | D83: =IF(C83<B83, B83+14, C83) -> 45232 | E83: =C83-B83 -> 2 | F83: =D83-B83 -> 2 | G83: =IF(Table1[[#This Row],[CorrectedLeadTimeDays]]<=7, 1, 0) -> 1 | H83: =TEXT(B83, "mmmm") -> October | I83: ="Q"&ROUNDUP(MONTH(B83)/3,0)&"-"&YEAR(B83) -> Q4-2023 | J83: =TEXT(K83, "yyyy-mm") -> 2023-01 | K83: =_xlfn.MINIFS($B:$B,$M:$M,M83) -> 44946 | L83: Africa | M83: Kenya | N83: Kisumu | O83: Education | P83: Retail | Q83: O. Wang | R83: =DATEDIF(K83,B83,"m") -> 9 | S83: Accessories | T83: ACC-4124 | U83: 867.89 | V83: =Table1[[#This Row],[UnitCost]]*(1+WhatIf!$B$3) -> 911.2845 | W83: =U83*AI83 -> 8678.9 | X83: =Table1[[#This Row],[ScenarioRev]]-Table1[[#This Row],[ScenarioUnitCost]] -> 11205.777 | Y83: 1349.94 | Z83: =Y83*AI83*(1-AD83) -> 11015.51 | AA83: =Table1[[#This Row],[ScenarioQuanity]]*Table1[[#This Row],[UnitPrice]]*(1-Table1[[#This Row],[ScenarioDiscPct]]) -> 12117.061 | AB83: =Z83-W83 -> 2336.6104 | AC83: =Table1[[#This Row],[ScenarioRev]] - Table1[[#This Row],[ScenarioCostOfGoods]] -> 911.2845 | AD83: 0.184 | AE83: =MIN(Table1[[#This Row],[DiscountPct]], WhatIf!$B$2) -> 0.184 | AF83: =IF(Table1[[#This Row],[DiscountPct]]>0.2, 1, 0) -> 0 | AG83: =IF(Y83<=_xlfn.PERCENTILE.INC($Y:$Y,0.33),"Low", IF(D83<=_xlfn.PERCENTILE.INC($Y:$Y,0.66),"Medium", "High")) -> High | AH83: =IF(Z83=0, 0, AB83/Z83) -> 0.21212003 | AI83: 10 | AJ83: =Table1[[#This Row],[Quantity]]*(1+WhatIf!$B$4) -> 11
A84: ORD-2025-262434 | B84: 45827 | C84: 45829 | D84: =IF(C84<B84, B84+14, C84) -> 45829 | E84: =C84-B84 -> 2 | F84: =D84-B84 -> 2 | G84: =IF(Table1[[#This Row],[CorrectedLeadTimeDays]]<=7, 1, 0) -> 1 | H84: =TEXT(B84, "mmmm") -> June | I84: ="Q"&ROUNDUP(MONTH(B84)/3,0)&"-"&YEAR(B84) -> Q2-2025 | J84: =TEXT(K84, "yyyy-mm") -> 2023-01 | K84: =_xlfn.MINIFS($B:$B,$M:$M,M84) -> 44933 | L84: Africa | M84: South Africa | N84: Johannesburg | O84: Small Business | Q84: H. Kim | R84: =DATEDIF(K84,B84,"m") -> 29 | S84: Phones | T84: PHN-7379 | U84: 1466.27 | V84: =Table1[[#This Row],[UnitCost]]*(1+WhatIf!$B$3) -> 1539.5835 | W84: =U84*AI84 -> 13196.43 | X84: =Table1[[#This Row],[ScenarioRev]]-Table1[[#This Row],[ScenarioUnitCost]] -> 30552.956 | Y84: 3589.89 | Z84: =Y84*AI84*(1-AD84) -> 29175.036 | AA84: =Table1[[#This Row],[ScenarioQuanity]]*Table1[[#This Row],[UnitPrice]]*(1-Table1[[#This Row],[ScenarioDiscPct]]) -> 32092.54 | AB84: =Z84-W84 -> 15978.606 | AC84: =Table1[[#This Row],[ScenarioRev]] - Table1[[#This Row],[ScenarioCostOfGoods]] -> 1539.5835 | AD84: 0.097 | AE84: =MIN(Table1[[#This Row],[DiscountPct]], WhatIf!$B$2) -> 0.097 | AF84: =IF(Table1[[#This Row],[DiscountPct]]>0.2, 1, 0) -> 0 | AG84: =IF(Y84<=_xlfn.PERCENTILE.INC($Y:$Y,0.33),"Low", IF(D84<=_xlfn.PERCENTILE.INC($Y:$Y,0.66),"Medium", "High")) -> High | AH84: =IF(Z84=0, 0, AB84/Z84) -> 0.54768076 | AI84: 9 | AJ84: =Table1[[#This Row],[Quantity]]*(1+WhatIf!$B$4) -> 9.9
A85: ORD-2024-257550 | B85: 45653 | C85: 45655 | D85: =IF(C85<B85, B85+14, C85) -> 45655 | E85: =C85-B85 -> 2 | F85: =D85-B85 -> 2 | G85: =IF(Table1[[#This Row],[CorrectedLeadTimeDays]]<=7, 1, 0) -> 1 | H85: =TEXT(B85, "mmmm") -> December | I85: ="Q"&ROUNDUP(MONTH(B85)/3,0)&"-"&YEAR(B85) -> Q4-2024 | J85: =TEXT(K85, "yyyy-mm") -> 2023-01 | K85: =_xlfn.MINIFS($B:$B,$M:$M,M85) -> 44928 | L85: Americas | M85: Canada | N85: Vancouver | O85: Enterprise | P85: Marketplace | Q85: C. Otieno | R85: =DATEDIF(K85,B85,"m") -> 23 | S85: Accessories | T85: ACC-8620 | U85: 1146.72 | V85: =Table1[[#This Row],[UnitCost]]*(1+WhatIf!$B$3) -> 1204.056 | W85: =U85*AI85 -> 9173.76 | X85: =Table1[[#This Row],[ScenarioRev]]-Table1[[#This Row],[ScenarioUnitCost]] -> 15023.921 | Y85: 2074.34 | Z85: =Y85*AI85*(1-AD85) -> 14752.706 | AA85: =Table1[[#This Row],[ScenarioQuanity]]*Table1[[#This Row],[UnitPrice]]*(1-Table1[[#This Row],[ScenarioDiscPct]]) -> 16227.977 | AB85: =Z85-W85 -> 5578.9461 | AC85: =Table1[[#This Row],[ScenarioRev]] - Table1[[#This Row],[ScenarioCostOfGoods]] -> 1204.056 | AD85: 0.111 | AE85: =MIN(Table1[[#This Row],[DiscountPct]], WhatIf!$B$2) -> 0.111 | AF85: =IF(Table1[[#This Row],[DiscountPct]]>0.2, 1, 0) -> 0 | AG85: =IF(Y85<=_xlfn.PERCENTILE.INC($Y:$Y,0.33),"Low", IF(D85<=_xlfn.PERCENTILE.INC($Y:$Y,0.66),"Medium", "High")) -> High | AH85: =IF(Z85=0, 0, AB85/Z85) -> 0.37816425 | AI85: 8 | AJ85: =Table1[[#This Row],[Quantity]]*(1+WhatIf!$B$4) -> 8.8
A86: ORD-2024-499009 | B86: 45316 | C86: 45318 | D86: =IF(C86<B86, B86+14, C86) -> 45318 | E86: =C86-B86 -> 2 | F86: =D86-B86 -> 2 | G86: =IF(Table1[[#This Row],[CorrectedLeadTimeDays]]<=7, 1, 0) -> 1 | H86: =TEXT(B86, "mmmm") -> January | I86: ="Q"&ROUNDUP(MONTH(B86)/3,0)&"-"&YEAR(B86) -> Q1-2024 | J86: =TEXT(K86, "yyyy-mm") -> 2023-01 | K86: =_xlfn.MINIFS($B:$B,$M:$M,M86) -> 44955 | L86: Americas | M86: Brazil | N86: São Paulo | O86: Non-Profit | P86: Marketplace | Q86: N. Brown | R86: =DATEDIF(K86,B86,"m") -> 11 | S86: Laptops | T86: LAP-7056 | U86: 1410.97 | V86: =Table1[[#This Row],[UnitCost]]*(1+WhatIf!$B$3) -> 1481.5185 | W86: =U86*AI86 -> 8465.82 | X86: =Table1[[#This Row],[ScenarioRev]]-Table1[[#This Row],[ScenarioUnitCost]] -> 7942.6133 | Y86: 1650.75 | Z86: =Y86*AI86*(1-AD86) -> 8567.3925 | AA86: =Table1[[#This Row],[ScenarioQuanity]]*Table1[[#This Row],[UnitPrice]]*(1-Table1[[#This Row],[ScenarioDiscPct]]) -> 9424.1318 | AB86: =Z86-W86 -> 101.5725 | AC86: =Table1[[#This Row],[ScenarioRev]] - Table1[[#This Row],[ScenarioCostOfGoods]] -> 1481.5185 | AD86: 0.135 | AE86: =MIN(Table1[[#This Row],[DiscountPct]], WhatIf!$B$2) -> 0.135 | AF86: =IF(Table1[[#This Row],[DiscountPct]]>0.2, 1, 0) -> 0 | AG86: =IF(Y86<=_xlfn.PERCENTILE.INC($Y:$Y,0.33),"Low", IF(D86<=_xlfn.PERCENTILE.INC($Y:$Y,0.66),"Medium", "High")) -> High | AH86: =IF(Z86=0, 0, AB86/Z86) -> 0.011855708 | AI86: 6 | AJ86: =Table1[[#This Row],[Quantity]]*(1+WhatIf!$B$4) -> 6.6
A87: ORD-2023-235230 | B87: 45168 | C87: 45170 | D87: =IF(C87<B87, B87+14, C87) -> 45170 | E87: =C87-B87 -> 2 | F87: =D87-B87 -> 2 | G87: =IF(Table1[[#This Row],[CorrectedLeadTimeDays]]<=7, 1, 0) -> 1 | H87: =TEXT(B87, "mmmm") -> August | I87: ="Q"&ROUNDUP(MONTH(B87)/3,0)&"-"&YEAR(B87) -> Q3-2023 | J87: =TEXT(K87, "yyyy-mm") -> 2023-01 | K87: =_xlfn.MINIFS($B:$B,$M:$M,M87) -> 44948 | L87: Europe | M87: Germany | N87: Munich | O87: Corporate | P87: Direct | Q87: N. Brown | R87: =DATEDIF(K87,B87,"m") -> 7 | S87: Networking | T87: NET-9989 | U87: 44.42 | V87: =Table1[[#This Row],[UnitCost]]*(1+WhatIf!$B$3) -> 46.641 | W87: =U87*AI87 -> 266.52 | X87: =Table1[[#This Row],[ScenarioRev]]-Table1[[#This Row],[ScenarioUnitCost]] -> 190.07724 | Y87: 41.9 | Z87: =Y87*AI87*(1-AD87) -> 215.1984 | AA87: =Table1[[#This Row],[ScenarioQuanity]]*Table1[[#This Row],[UnitPrice]]*(1-Table1[[#This Row],[ScenarioDiscPct]]) -> 236.71824 | AB87: =Z87-W87 -> -51.3216 | AC87: =Table1[[#This Row],[ScenarioRev]] - Table1[[#This Row],[ScenarioCostOfGoods]] -> 46.641 | AD87: 0.144 | AE87: =MIN(Table1[[#This Row],[DiscountPct]], WhatIf!$B$2) -> 0.144 | AF87: =IF(Table1[[#This Row],[DiscountPct]]>0.2, 1, 0) -> 0 | AG87: =IF(Y87<=_xlfn.PERCENTILE.INC($Y:$Y,0.33),"Low", IF(D87<=_xlfn.PERCENTILE.INC($Y:$Y,0.66),"Medium", "High")) -> Low | AH87: =IF(Z87=0, 0, AB87/Z87) -> -0.23848504 | AI87: 6 | AJ87: =Table1[[#This Row],[Quantity]]*(1+WhatIf!$B$4) -> 6.6
A88: ORD-2024-206311 | B88: 45304 | C88: 45306 | D88: =IF(C88<B88, B88+14, C88) -> 45306 | E88: =C88-B88 -> 2 | F88: =D88-B88 -> 2 | G88: =IF(Table1[[#This Row],[CorrectedLeadTimeDays]]<=7, 1, 0) -> 1 | H88: =TEXT(B88, "mmmm") -> January | I88: ="Q"&ROUNDUP(MONTH(B88)/3,0)&"-"&YEAR(B88) -> Q1-2024 | J88: =TEXT(K88, "yyyy-mm") -> 2023-01 | K88: =_xlfn.MINIFS($B:$B,$M:$M,M88) -> 44939 | L88: Americas | M88: USA | N88: San Francisco | O88: Non-Profit | P88: Direct | Q88: E. Garcia | R88: =DATEDIF(K88,B88,"m") -> 12 | S88: Components | T88: CMP-2410 | U88: 1061.37 | V88: =Table1[[#This Row],[UnitCost]]*(1+WhatIf!$B$3) -> 1114.4385 | W88: =U88*AI88 -> 4245.48 | X88: =Table1[[#This Row],[ScenarioRev]]-Table1[[#This Row],[ScenarioUnitCost]] -> 5964.3427 | Y88: 1938.33 | Z88: =Y88*AI88*(1-AD88) -> 6435.2556 | AA88: =Table1[[#This Row],[ScenarioQuanity]]*Table1[[#This Row],[UnitPrice]]*(1-Table1[[#This Row],[ScenarioDiscPct]]) -> 7078.7812 | AB88: =Z88-W88 -> 2189.7756 | AC88: =Table1[[#This Row],[ScenarioRev]] - Table1[[#This Row],[ScenarioCostOfGoods]] -> 1114.4385 | AD88: 0.17 | AE88: =MIN(Table1[[#This Row],[DiscountPct]], WhatIf!$B$2) -> 0.17 | AF88: =IF(Table1[[#This Row],[DiscountPct]]>0.2, 1, 0) -> 0 | AG88: =IF(Y88<=_xlfn.PERCENTILE.INC($Y:$Y,0.33),"Low", IF(D88<=_xlfn.PERCENTILE.INC($Y:$Y,0.66),"Medium", "High")) -> High | AH88: =IF(Z88=0, 0, AB88/Z88) -> 0.34027795 | AI88: 4 | AJ88: =Table1[[#This Row],[Quantity]]*(1+WhatIf!$B$4) -> 4.4
A89: ORD-2025-650841 | B89: 45841 | C89: 45844 | D89: =IF(C89<B89, B89+14, C89) -> 45844 | E89: =C89-B89 -> 3 | F89: =D89-B89 -> 3 | G89: =IF(Table1[[#This Row],[CorrectedLeadTimeDays]]<=7, 1, 0) -> 1 | H89: =TEXT(B89, "mmmm") -> July | I89: ="Q"&ROUNDUP(MONTH(B89)/3,0)&"-"&YEAR(B89) -> Q3-2025 | J89: =TEXT(K89, "yyyy-mm") -> 2023-01 | K89: =_xlfn.MINIFS($B:$B,$M:$M,M89) -> 44941 | L89: Africa | M89: Nigeria | N89: Lagos | O89: Consumer | P89: Online | R89: =DATEDIF(K89,B89,"m") -> 29 | S89: Laptops | T89: LAP-8910 | U89: 1313.3 | V89: =Table1[[#This Row],[UnitCost]]*(1+WhatIf!$B$3) -> 1378.965 | W89: =U89*AI89 -> 55158.6 | X89: =Table1[[#This Row],[ScenarioRev]]-Table1[[#This Row],[ScenarioUnitCost]] -> 110956.27 | Y89: 2884.34 | Z89: =Y89*AI89*(1-AD89) -> 102122.94 | AA89: =Table1[[#This Row],[ScenarioQuanity]]*Table1[[#This Row],[UnitPrice]]*(1-Table1[[#This Row],[ScenarioDiscPct]]) -> 112335.24 | AB89: =Z89-W89 -> 46964.342 | AC89: =Table1[[#This Row],[ScenarioRev]] - Table1[[#This Row],[ScenarioCostOfGoods]] -> 1378.965 | AD89: 0.157 | AE89: =MIN(Table1[[#This Row],[DiscountPct]], WhatIf!$B$2) -> 0.157 | AF89: =IF(Table1[[#This Row],[DiscountPct]]>0.2, 1, 0) -> 0 | AG89: =IF(Y89<=_xlfn.PERCENTILE.INC($Y:$Y,0.33),"Low", IF(D89<=_xlfn.PERCENTILE.INC($Y:$Y,0.66),"Medium", "High")) -> High | AH89: =IF(Z89=0, 0, AB89/Z89) -> 0.45988043 | AI89: 42 | AJ89: =Table1[[#This Row],[Quantity]]*(1+WhatIf!$B$4) -> 46.2
A90: ORD-2023-609394 | B90: 45032 | C90: 45035 | D90: =IF(C90<B90, B90+14, C90) -> 45035 | E90: =C90-B90 -> 3 | F90: =D90-B90 -> 3 | G90: =IF(Table1[[#This Row],[CorrectedLeadTimeDays]]<=7, 1, 0) -> 1 | H90: =TEXT(B90, "mmmm") -> April | I90: ="Q"&ROUNDUP(MONTH(B90)/3,0)&"-"&YEAR(B90) -> Q2-2023 | J90: =TEXT(K90, "yyyy-mm") -> 2023-01 | K90: =_xlfn.MINIFS($B:$B,$M:$M,M90) -> 44948 | L90: Europe | M90: Germany | N90: Munich | O90: Corporate | P90: Direct | Q90: B. Chen | R90: =DATEDIF(K90,B90,"m") -> 2 | S90: Accessories | T90: ACC-1731 | U90: 553.61 | V90: =Table1[[#This Row],[UnitCost]]*(1+WhatIf!$B$3) -> 581.2905 | W90: =U90*AI90 -> 18269.13 | X90: =Table1[[#This Row],[ScenarioRev]]-Table1[[#This Row],[ScenarioUnitCost]] -> 24301.655 | Y90: 699.47 | Z90: =Y90*AI90*(1-AD90) -> 22620.86 | AA90: =Table1[[#This Row],[ScenarioQuanity]]*Table1[[#This Row],[UnitPrice]]*(1-Table1[[#This Row],[ScenarioDiscPct]]) -> 24882.946 | AB90: =Z90-W90 -> 4351.7298 | AC90: =Table1[[#This Row],[ScenarioRev]] - Table1[[#This Row],[ScenarioCostOfGoods]] -> 581.2905 | AD90: 0.02 | AE90: =MIN(Table1[[#This Row],[DiscountPct]], WhatIf!$B$2) -> 0.02 | AF90: =IF(Table1[[#This Row],[DiscountPct]]>0.2, 1, 0) -> 0 | AG90: =IF(Y90<=_xlfn.PERCENTILE.INC($Y:$Y,0.33),"Low", IF(D90<=_xlfn.PERCENTILE.INC($Y:$Y,0.66),"Medium", "High")) -> Low | AH90: =IF(Z90=0, 0, AB90/Z90) -> 0.19237685 | AI90: 33 | AJ90: =Table1[[#This Row],[Quantity]]*(1+WhatIf!$B$4) -> 36.3
A91: ORD-2023-159379 | B91: 44965 | C91: 44968 | D91: =IF(C91<B91, B91+14, C91) -> 44968 | E91: =C91-B91 -> 3 | F91: =D91-B91 -> 3 | G91: =IF(Table1[[#This Row],[CorrectedLeadTimeDays]]<=7, 1, 0) -> 1 | H91: =TEXT(B91, "mmmm") -> February | I91: ="Q"&ROUNDUP(MONTH(B91)/3,0)&"-"&YEAR(B91) -> Q1-2023 | J91: =TEXT(K91, "yyyy-mm") -> 2023-01 | K91: =_xlfn.MINIFS($B:$B,$M:$M,M91) -> 44933 | L91: Africa | M91: South Africa | N91: Cape Town | O91: Corporate | P91: Direct | Q91: M. Rossi | R91: =DATEDIF(K91,B91,"m") -> 1 | S91: Networking | T91: NET-5018 | U91: 1410.05 | V91: =Table1[[#This Row],[UnitCost]]*(1+WhatIf!$B$3) -> 1480.5525 | W91: =U91*AI91 -> 36661.3 | X91: =Table1[[#This Row],[ScenarioRev]]-Table1[[#This Row],[ScenarioUnitCost]] -> 64841.533 | Y91: 2763.95 | Z91: =Y91*AI91*(1-AD91) -> 60292.805 | AA91: =Table1[[#This Row],[ScenarioQuanity]]*Table1[[#This Row],[UnitPrice]]*(1-Table1[[#This Row],[ScenarioDiscPct]]) -> 66322.086 | AB91: =Z91-W91 -> 23631.505 | AC91: =Table1[[#This Row],[ScenarioRev]] - Table1[[#This Row],[ScenarioCostOfGoods]] -> 1480.5525 | AD91: 0.161 | AE91: =MIN(Table1[[#This Row],[DiscountPct]], WhatIf!$B$2) -> 0.161 | AF91: =IF(Table1[[#This Row],[DiscountPct]]>0.2, 1, 0) -> 0 | AG91: =IF(Y91<=_xlfn.PERCENTILE.INC($Y:$Y,0.33),"Low", IF(D91<=_xlfn.PERCENTILE.INC($Y:$Y,0.66),"Medium", "High")) -> High | AH91: =IF(Z91=0, 0, AB91/Z91) -> 0.39194569 | AI91: 26 | AJ91: =Table1[[#This Row],[Quantity]]*(1+WhatIf!$B$4) -> 28.6
A92: ORD-2024-446030 | B92: 45374 | C92: 45377 | D92: =IF(C92<B92, B92+14, C92) -> 45377 | E92: =C92-B92 -> 3 | F92: =D92-B92 -> 3 | G92: =IF(Table1[[#This Row],[CorrectedLeadTimeDays]]<=7, 1, 0) -> 1 | H92: =TEXT(B92, "mmmm") -> March | I92: ="Q"&ROUNDUP(MONTH(B92)/3,0)&"-"&YEAR(B92) -> Q1-2024 | J92: =TEXT(K92, "yyyy-mm") -> 2023-01 | K92: =_xlfn.MINIFS($B:$B,$M:$M,M92) -> 44955 | L92: Asia | M92: India | N92: Bengaluru | O92: Education | P92: Direct | Q92: G. Dubois | R92: =DATEDIF(K92,B92,"m") -> 13 | S92: Phones | T92: PHN-4346 | U92: 382.21 | V92: =Table1[[#This Row],[UnitCost]]*(1+WhatIf!$B$3) -> 401.3205 | W92: =U92*AI92 -> 9937.46 | X92: =Table1[[#This Row],[ScenarioRev]]-Table1[[#This Row],[ScenarioUnitCost]] -> 13534.038 | Y92: 571.89 | Z92: =Y92*AI92*(1-AD92) -> 12668.507 | AA92: =Table1[[#This Row],[ScenarioQuanity]]*Table1[[#This Row],[UnitPrice]]*(1-Table1[[#This Row],[ScenarioDiscPct]]) -> 13935.358 | AB92: =Z92-W92 -> 2731.0473 | AC92: =Table1[[#This Row],[ScenarioRev]] - Table1[[#This Row],[ScenarioCostOfGoods]] -> 401.3205 | AD92: 0.148 | AE92: =MIN(Table1[[#This Row],[DiscountPct]], WhatIf!$B$2) -> 0.148 | AF92: =IF(Table1[[#This Row],[DiscountPct]]>0.2, 1, 0) -> 0 | AG92: =IF(Y92<=_xlfn.PERCENTILE.INC($Y:$Y,0.33),"Low", IF(D92<=_xlfn.PERCENTILE.INC($Y:$Y,0.66),"Medium", "High")) -> Low | AH92: =IF(Z92=0, 0, AB92/Z92) -> 0.21557767 | AI92: 26 | AJ92: =Table1[[#This Row],[Quantity]]*(1+WhatIf!$B$4) -> 28.6
A93: ORD-2024-468615 | B93: 45482 | C93: 45485 | D93: =IF(C93<B93, B93+14, C93) -> 45485 | E93: =C93-B93 -> 3 | F93: =D93-B93 -> 3 | G93: =IF(Table1[[#This Row],[CorrectedLeadTimeDays]]<=7, 1, 0) -> 1 | H93: =TEXT(B93, "mmmm") -> July | I93: ="Q"&ROUNDUP(MONTH(B93)/3,0)&"-"&YEAR(B93) -> Q3-2024 | J93: =TEXT(K93, "yyyy-mm") -> 2023-01 | K93: =_xlfn.MINIFS($B:$B,$M:$M,M93) -> 44938 | L93: Asia | M93: China | N93: Shanghai | O93: Small Business | P93: Retail | Q93: D. Smith | R93: =DATEDIF(K93,B93,"m") -> 17 | S93: Accessories | T93: ACC-3721 | U93: 748.39 | V93: =Table1[[#This Row],[UnitCost]]*(1+WhatIf!$B$3) -> 785.8095 | W93: =U93*AI93 -> 17212.97 | X93: =Table1[[#This Row],[ScenarioRev]]-Table1[[#This Row],[ScenarioUnitCost]] -> 23993.517 | Y93: 979.42 | Z93: =Y93*AI93*(1-AD93) -> 22526.66 | AA93: =Table1[[#This Row],[ScenarioQuanity]]*Table1[[#This Row],[UnitPrice]]*(1-Table1[[#This Row],[ScenarioDiscPct]]) -> 24779.326 | AB93: =Z93-W93 -> 5313.69 | AC93: =Table1[[#This Row],[ScenarioRev]] - Table1[[#This Row],[ScenarioCostOfGoods]] -> 785.8095 | AD93: 0 | AE93: =MIN(Table1[[#This Row],[DiscountPct]], WhatIf!$B$2) -> 0 | AF93: =IF(Table1[[#This Row],[DiscountPct]]>0.2, 1, 0) -> 0 | AG93: =IF(Y93<=_xlfn.PERCENTILE.INC($Y:$Y,0.33),"Low", IF(D93<=_xlfn.PERCENTILE.INC($Y:$Y,0.66),"Medium", "High")) -> High | AH93: =IF(Z93=0, 0, AB93/Z93) -> 0.2358845 | AI93: 23 | AJ93: =Table1[[#This Row],[Quantity]]*(1+WhatIf!$B$4) -> 25.3
A94: ORD-2024-626750 | B94: 45516 | C94: 45519 | D94: =IF(C94<B94, B94+14, C94) -> 45519 | E94: =C94-B94 -> 3 | F94: =D94-B94 -> 3 | G94: =IF(Table1[[#This Row],[CorrectedLeadTimeDays]]<=7, 1, 0) -> 1 | H94: =TEXT(B94, "mmmm") -> August | I94: ="Q"&ROUNDUP(MONTH(B94)/3,0)&"-"&YEAR(B94) -> Q3-2024 | J94: =TEXT(K94, "yyyy-mm") -> 2023-01 | K94: =_xlfn.MINIFS($B:$B,$M:$M,M94) -> 44939 | L94: Americas | M94: USA | N94: Chicago | O94: Corporate | P94: Marketplace | Q94: D. Smith | R94: =DATEDIF(K94,B94,"m") -> 18 | S94: Printers | T94: PRN-5591 | U94: 850.7 | V94: =Table1[[#This Row],[UnitCost]]*(1+WhatIf!$B$3) -> 893.235 | W94: =U94*AI94 -> 16163.3 | X94: =Table1[[#This Row],[ScenarioRev]]-Table1[[#This Row],[ScenarioUnitCost]] -> 18276.646 | Y94: 1118.56 | Z94: =Y94*AI94*(1-AD94) -> 17427.165 | AA94: =Table1[[#This Row],[ScenarioQuanity]]*Table1[[#This Row],[UnitPrice]]*(1-Table1[[#This Row],[ScenarioDiscPct]]) -> 19169.881 | AB94: =Z94-W94 -> 1263.8648 | AC94: =Table1[[#This Row],[ScenarioRev]] - Table1[[#This Row],[ScenarioCostOfGoods]] -> 893.235 | AD94: 0.18 | AE94: =MIN(Table1[[#This Row],[DiscountPct]], WhatIf!$B$2) -> 0.18 | AF94: =IF(Table1[[#This Row],[DiscountPct]]>0.2, 1, 0) -> 0 | AG94: =IF(Y94<=_xlfn.PERCENTILE.INC($Y:$Y,0.33),"Low", IF(D94<=_xlfn.PERCENTILE.INC($Y:$Y,0.66),"Medium", "High")) -> High | AH94: =IF(Z94=0, 0, AB94/Z94) -> 0.072522686 | AI94: 19 | AJ94: =Table1[[#This Row],[Quantity]]*(1+WhatIf!$B$4) -> 20.9
A95: ORD-2023-619385 | B95: 45199 | C95: 45202 | D95: =IF(C95<B95, B95+14, C95) -> 45202 | E95: =C95-B95 -> 3 | F95: =D95-B95 -> 3 | G95: =IF(Table1[[#This Row],[CorrectedLeadTimeDays]]<=7, 1, 0) -> 1 | H95: =TEXT(B95, "mmmm") -> September | I95: ="Q"&ROUNDUP(MONTH(B95)/3,0)&"-"&YEAR(B95) -> Q3-2023 | J95: =TEXT(K95, "yyyy-mm") -> 2023-01 | K95: =_xlfn.MINIFS($B:$B,$M:$M,M95) -> 44938 | L95: Asia | M95: China | N95: Beijing | O95: Non-Profit | P95: Retail | Q95: J. Njeri | R95: =DATEDIF(K95,B95,"m") -> 8 | S95: Laptops | T95: LAP-5763 | U95: 1019.36 | V95: =Table1[[#This Row],[UnitCost]]*(1+WhatIf!$B$3) -> 1070.328 | W95: =U95*AI95 -> 17329.12 | X95: =Table1[[#This Row],[ScenarioRev]]-Table1[[#This Row],[ScenarioUnitCost]] -> 14448.657 | Y95: 972.91 | Z95: =Y95*AI95*(1-AD95) -> 14108.168 | AA95: =Table1[[#This Row],[ScenarioQuanity]]*Table1[[#This Row],[UnitPrice]]*(1-Table1[[#This Row],[ScenarioDiscPct]]) -> 15518.985 | AB95: =Z95-W95 -> -3220.9521 | AC95: =Table1[[#This Row],[ScenarioRev]] - Table1[[#This Row],[ScenarioCostOfGoods]] -> 1070.328 | AD95: 0.147 | AE95: =MIN(Table1[[#This Row],[DiscountPct]], WhatIf!$B$2) -> 0.147 | AF95: =IF(Table1[[#This Row],[DiscountPct]]>0.2, 1, 0) -> 0 | AG95: =IF(Y95<=_xlfn.PERCENTILE.INC($Y:$Y,0.33),"Low", IF(D95<=_xlfn.PERCENTILE.INC($Y:$Y,0.66),"Medium", "High")) -> High | AH95: =IF(Z95=0, 0, AB95/Z95) -> -0.22830407 | AI95: 17 | AJ95: =Table1[[#This Row],[Quantity]]*(1+WhatIf!$B$4) -> 18.7
A96: ORD-2024-766980 | B96: 45600 | C96: 45603 | D96: =IF(C96<B96, B96+14, C96) -> 45603 | E96: =C96-B96 -> 3 | F96: =D96-B96 -> 3 | G96: =IF(Table1[[#This Row],[CorrectedLeadTimeDays]]<=7, 1, 0) -> 1 | H96: =TEXT(B96, "mmmm") -> November | I96: ="Q"&ROUNDUP(MONTH(B96)/3,0)&"-"&YEAR(B96) -> Q4-2024 | J96: =TEXT(K96, "yyyy-mm") -> 2023-01 | K96: =_xlfn.MINIFS($B:$B,$M:$M,M96) -> 44936 | L96: Europe | M96: France | N96: Lyon | O96: Corporate | P96: Online | Q96: O. Wang | R96: =DATEDIF(K96,B96,"m") -> 21 | S96: Monitors | T96: MON-1118 | U96: 740.68 | V96: =Table1[[#This Row],[UnitCost]]*(1+WhatIf!$B$3) -> 777.714 | W96: =U96*AI96 -> 12591.56 | X96: =Table1[[#This Row],[ScenarioRev]]-Table1[[#This Row],[ScenarioUnitCost]] -> 26809.715 | Y96: 1837.19 | Z96: =Y96*AI96*(1-AD96) -> 25079.481 | AA96: =Table1[[#This Row],[ScenarioQuanity]]*Table1[[#This Row],[UnitPrice]]*(1-Table1[[#This Row],[ScenarioDiscPct]]) -> 27587.429 | AB96: =Z96-W96 -> 12487.921 | AC96: =Table1[[#This Row],[ScenarioRev]] - Table1[[#This Row],[ScenarioCostOfGoods]] -> 777.714 | AD96: 0.197 | AE96: =MIN(Table1[[#This Row],[DiscountPct]], WhatIf!$B$2) -> 0.197 | AF96: =IF(Table1[[#This Row],[DiscountPct]]>0.2, 1, 0) -> 0 | AG96: =IF(Y96<=_xlfn.PERCENTILE.INC($Y:$Y,0.33),"Low", IF(D96<=_xlfn.PERCENTILE.INC($Y:$Y,0.66),"Medium", "High")) -> High | AH96: =IF(Z96=0, 0, AB96/Z96) -> 0.49793378 | AI96: 17 | AJ96: =Table1[[#This Row],[Quantity]]*(1+WhatIf!$B$4) -> 18.7
A97: ORD-2024-170021 | B97: 45601 | C97: 45604 | D97: =IF(C97<B97, B97+14, C97) -> 45604 | E97: =C97-B97 -> 3 | F97: =D97-B97 -> 3 | G97: =IF(Table1[[#This Row],[CorrectedLeadTimeDays]]<=7, 1, 0) -> 1 | H97: =TEXT(B97, "mmmm") -> November | I97: ="Q"&ROUNDUP(MONTH(B97)/3,0)&"-"&YEAR(B97) -> Q4-2024 | J97: =TEXT(K97, "yyyy-mm") -> 2023-01 | K97: =_xlfn.MINIFS($B:$B,$M:$M,M97) -> 44928 | L97: Americas | M97: Canada | N97: Toronto | O97: Education | P97: Marketplace | Q97: O. Wang | R97: =DATEDIF(K97,B97,"m") -> 22 | S97: Components | T97: CMP-2015 | U97: 1020.4 | V97: =Table1[[#This Row],[UnitCost]]*(1+WhatIf!$B$3) -> 1071.42 | W97: =U97*AI97 -> 16326.4 | X97: =Table1[[#This Row],[ScenarioRev]]-Table1[[#This Row],[ScenarioUnitCost]] -> 17569.281 | Y97: 1184.71 | Z97: =Y97*AI97*(1-AD97) -> 16946.092 | AA97: =Table1[[#This Row],[ScenarioQuanity]]*Table1[[#This Row],[UnitPrice]]*(1-Table1[[#This Row],[ScenarioDiscPct]]) -> 18640.701 | AB97: =Z97-W97 -> 619.69184 | AC97: =Table1[[#This Row],[ScenarioRev]] - Table1[[#This Row],[ScenarioCostOfGoods]] -> 1071.42 | AD97: 0.106 | AE97: =MIN(Table1[[#This Row],[DiscountPct]], WhatIf!$B$2) -> 0.106 | AF97: =IF(Table1[[#This Row],[DiscountPct]]>0.2, 1, 0) -> 0 | AG97: =IF(Y97<=_xlfn.PERCENTILE.INC($Y:$Y,0.33),"Low", IF(D97<=_xlfn.PERCENTILE.INC($Y:$Y,0.66),"Medium", "High")) -> High | AH97: =IF(Z97=0, 0, AB97/Z97) -> 0.036568422 | AI97: 16 | AJ97: =Table1[[#This Row],[Quantity]]*(1+WhatIf!$B$4) -> 17.6
A98: ORD-2023-674887 | B98: 45276 | C98: 45279 | D98: =IF(C98<B98, B98+14, C98) -> 45279 | E98: =C98-B98 -> 3 | F98: =D98-B98 -> 3 | G98: =IF(Table1[[#This Row],[CorrectedLeadTimeDays]]<=7, 1, 0) -> 1 | H98: =TEXT(B98, "mmmm") -> December | I98: ="Q"&ROUNDUP(MONTH(B98)/3,0)&"-"&YEAR(B98) -> Q4-2023 | J98: =TEXT(K98, "yyyy-mm") -> 2023-01 | K98: =_xlfn.MINIFS($B:$B,$M:$M,M98) -> 44938 | L98: Asia | M98: China | N98: Beijing | O98: Education | P98: Retail | Q98: A. Patel | R98: =DATEDIF(K98,B98,"m") -> 11 | S98: Accessories | T98: ACC-9644 | U98: 1415.05 | V98: =Table1[[#This Row],[UnitCost]]*(1+WhatIf!$B$3) -> 1485.8025 | W98: =U98*AI98 -> 16980.6 | X98: =Table1[[#This Row],[ScenarioRev]]-Table1[[#This Row],[ScenarioUnitCost]] -> 24549.614 | Y98: 1972.38 | Z98: =Y98*AI98*(1-AD98) -> 23668.56 | AA98: =Table1[[#This Row],[ScenarioQuanity]]*Table1[[#This Row],[UnitPrice]]*(1-Table1[[#This Row],[ScenarioDiscPct]]) -> 26035.416 | AB98: =Z98-W98 -> 6687.96 | AC98: =Table1[[#This Row],[ScenarioRev]] - Table1[[#This Row],[ScenarioCostOfGoods]] -> 1485.8025 | AD98: 0 | AE98: =MIN(Table1[[#This Row],[DiscountPct]], WhatIf!$B$2) -> 0 | AF98: =IF(Table1[[#This Row],[DiscountPct]]>0.2, 1, 0) -> 0 | AG98: =IF(Y98<=_xlfn.PERCENTILE.INC($Y:$Y,0.33),"Low", IF(D98<=_xlfn.PERCENTILE.INC($Y:$Y,0.66),"Medium", "High")) -> High | AH98: =IF(Z98=0, 0, AB98/Z98) -> 0.28256725 | AI98: 12 | AJ98: =Table1[[#This Row],[Quantity]]*(1+WhatIf!$B$4) -> 13.2
A99: ORD-2024-375848 | B99: 45430 | C99: 45433 | D99: =IF(C99<B99, B99+14, C99) -> 45433 | E99: =C99-B99 -> 3 | F99: =D99-B99 -> 3 | G99: =IF(Table1[[#This Row],[CorrectedLeadTimeDays]]<=7, 1, 0) -> 1 | H99: =TEXT(B99, "mmmm") -> May | I99: ="Q"&ROUNDUP(MONTH(B99)/3,0)&"-"&YEAR(B99) -> Q2-2024 | J99: =TEXT(K99, "yyyy-mm") -> 2023-01 | K99: =_xlfn.MINIFS($B:$B,$M:$M,M99) -> 44936 | L99: Europe | M99: France | N99: Marseille | O99: Non-Profit | P99: Marketplace | Q99: D. Smith | R99: =DATEDIF(K99,B99,"m") -> 16 | S99: Printers | T99: PRN-1725 | U99: 663.66 | V99: =Table1[[#This Row],[UnitCost]]*(1+WhatIf!$B$3) -> 696.843 | W99: =U99*AI99 -> 7300.26 | X99: =Table1[[#This Row],[ScenarioRev]]-Table1[[#This Row],[ScenarioUnitCost]] -> 7281.9938 | Y99: 824.26 | Z99: =Y99*AI99*(1-AD99) -> 6899.8805 | AA99: =Table1[[#This Row],[ScenarioQuanity]]*Table1[[#This Row],[UnitPrice]]*(1-Table1[[#This Row],[ScenarioDiscPct]]) -> 7978.8368 | AB99: =Z99-W99 -> -400.37954 | AC99: =Table1[[#This Row],[ScenarioRev]] - Table1[[#This Row],[ScenarioCostOfGoods]] -> 696.843 | AD99: 0.239 | AE99: =MIN(Table1[[#This Row],[DiscountPct]], WhatIf!$B$2) -> 0.2 | AF99: =IF(Table1[[#This Row],[DiscountPct]]>0.2, 1, 0) -> 1 | AG99: =IF(Y99<=_xlfn.PERCENTILE.INC($Y:$Y,0.33),"Low", IF(D99<=_xlfn.PERCENTILE.INC($Y:$Y,0.66),"Medium", "High")) -> High | AH99: =IF(Z99=0, 0, AB99/Z99) -> -0.058027026 | AI99: 11 | AJ99: =Table1[[#This Row],[Quantity]]*(1+WhatIf!$B$4) -> 12.1
A100: ORD-2024-287210 | B100: 45369 | C100: 45372 | D100: =IF(C100<B100, B100+14, C100) -> 45372 | E100: =C100-B100 -> 3 | F100: =D100-B100 -> 3 | G100: =IF(Table1[[#This Row],[CorrectedLeadTimeDays]]<=7, 1, 0) -> 1 | H100: =TEXT(B100, "mmmm") -> March | I100: ="Q"&ROUNDUP(MONTH(B100)/3,0)&"-"&YEAR(B100) -> Q1-2024 | J100: =TEXT(K100, "yyyy-mm") -> 2023-01 | K100: =_xlfn.MINIFS($B:$B,$M:$M,M100) -> 44948 | L100: Europe | M100: Germany | N100: Munich | O100: Small Business | P100: Online | Q100: M. Rossi | R100: =DATEDIF(K100,B100,"m") -> 13 | S100: Accessories | T100: ACC-2761 | U100: 910.63 | V100: =Table1[[#This Row],[UnitCost]]*(1+WhatIf!$B$3) -> 956.1615 | W100: =U100*AI100 -> 8195.67 | X100: =Table1[[#This Row],[ScenarioRev]]-Table1[[#This Row],[ScenarioUnitCost]] -> 10756.338 | Y100: 1269.4 | Z100: =Y100*AI100*(1-AD100) -> 10647.727 | AA100: =Table1[[#This Row],[ScenarioQuanity]]*Table1[[#This Row],[UnitPrice]]*(1-Table1[[#This Row],[ScenarioDiscPct]]) -> 11712.5 | AB100: =Z100-W100 -> 2452.0572 | AC100: =Table1[[#This Row],[ScenarioRev]] - Table1[[#This Row],[ScenarioCostOfGoods]] -> 956.1615 | AD100: 0.068 | AE100: =MIN(Table1[[#This Row],[DiscountPct]], WhatIf!$B$2) -> 0.068 | AF100: =IF(Table1[[#This Row],[DiscountPct]]>0.2, 1, 0) -> 0 | AG100: =IF(Y100<=_xlfn.PERCENTILE.INC($Y:$Y,0.33),"Low", IF(D100<=_xlfn.PERCENTILE.INC($Y:$Y,0.66),"Medium", "High")) -> High | AH100: =IF(Z100=0, 0, AB100/Z100) -> 0.23028926 | AI100: 9 | AJ100: =Table1[[#This Row],[Quantity]]*(1+WhatIf!$B$4) -> 9.9
